Workbook

Sheet Read Me
A2: YIELD HEALTHCARE — PMPM CARE MANAGEMENT PRICING MODEL
B4: This workbook models a new Yield Healthcare line of business: a PMPM (per member per month) care management program sold to risk-bearing provider groups and ACOs, spanning three population segments — Post-Acute Transitions, Peri-Operative Optimization, and Complex Chronic Care Management.
B6: Tabs:
B7: Assumptions — every input the model runs on (customer sizing, segment enrollment rates, PMPM fees, CMS billing capture, delivery cost, ramp curve, customer acquisition plan). Blue text = editable input.
B8: Segment Unit Economics — per-enrolled-member and per-customer revenue, cost, and margin for each of the three population segments, plus a blended total.
B9: 3-Year Build — customer cohort ramp (new signings, retention, enrollment maturity by relationship year) driving total revenue, cost, and gross profit.
B10: Summary — company-level rollup and a revenue-by-year chart.
B12: How to use it: change any blue cell on the Assumptions tab and every other tab recalculates. All dollar figures are illustrative planning assumptions unless a source is cited in an adjacent note.
B14: Sourced figures (verified July 2026): CMS reports 14.3M Medicare beneficiaries in an ACO for 2026 (511 MSSP ACOs covering 12.6M lives, 74 ACO REACH ACOs covering 1.7M lives); 2026 Medicare Physician Fee Schedule national average rates for CPT 99490 ($62), 99487 ($144), 99489 ($78 add-on), 99424 PCM ($88), 99495/99496 TCM (~$220/$298.60), HCPCS G0023/G0024 PIN (~$87/$54), and RPM codes 99453/99454/99457/99458 (~$22/$47/$52/$41). Enrollment rates, PMPM pricing, delivery cost, customer sizing, and the acquisition ramp are labeled planning assumptions for Yield Healthcare to refine with real underwriting data — this is a planning model, not a quote or a filed rate schedule.

Sheet Assumptions
A1: ASSUMPTIONS
A3: 1. CUSTOMER SIZING — covered/attributed lives per risk-bearing provider group
A4: Size tier | B4: Lives | C4: Mix %
A5: Small | B5: 15000 | C5: 0.5
A6: Medium | B6: 45000 | C6: 0.35
A7: Large | B7: 120000 | C7: 0.15
A8: Blended lives per customer | B8: =SUMPRODUCT(B5:B7,C5:C7) -> 41250
A9: Size mix is a planning assumption. For reference: CMS reports 511 MSSP ACOs covering 12.6M lives (avg ~24,700/ACO) and 74 ACO REACH ACOs covering 1.7M lives (avg ~23,000/ACO) in 2026 — the blended average above assumes Yield Healthcare's PMPM offering skews toward larger, better-resourced organizations able to fund an external vendor.
A12: 2. POPULATION SEGMENTS — enrollment rate (% of covered lives actively enrolled/month)
A13: Segment | B13: Enrollment rate
A14: Post-Acute Transitions | B14: 0.008
A15: Peri-Operative Optimization | B15: 0.005
A16: Complex Chronic CM | B16: 0.04
A18: Post-Acute Transitions: members with a recent acute stay or TEAM-eligible surgical episode, ~60-90 day intensive window. Peri-Operative: members with a scheduled major surgery, pre-op through recovery. Complex Chronic CM: multi-condition, high-HCC members in ongoing monthly management. Rates reflect the well-established finding that a small share of any population drives the majority of preventable cost and utilization.
A21: 3. PMPM CLIENT FEE — charged to the ACO/provider group per enrolled member per month
A22: Segment | B22: PMPM fee
A23: Post-Acute Transitions | B23: 175
A24: Peri-Operative Optimization | B24: 195
A25: Complex Chronic CM | B25: 85
A28: 4. CMS BILLING REVENUE — net to Yield Healthcare, per enrolled member per month
A29: Segment | B29: Net CMS billing PMPM
A30: Post-Acute Transitions | B30: 80
A31: Peri-Operative Optimization | B31: 85
A32: Complex Chronic CM | B32: 95
A34: Assumes a 60% contracted revenue-share on collected CM billing (same structure as Yield Healthcare's TEAM Embedded tier) — billing runs through the provider group's or an affiliated physician group's Medicare enrollment, not Yield Healthcare's own NPI. Post-Acute and Peri-Operative capture is largely episodic TCM/PIN revenue (CPT 99495/99496, HCPCS G0023/G0024), amortized here to a monthly-equivalent figure for modeling. Complex Chronic capture is genuinely recurring, blending complex CCM (99487/99489), PCM (99424+), and RPM (99453/99454/99457/99458).
A37: 5. DELIVERY COST — per enrolled member per month, staffing-driven
A38: Segment | B38: Delivery cost PMPM
A39: Post-Acute Transitions | B39: 115
A40: Peri-Operative Optimization | B40: 130
A41: Complex Chronic CM | B41: 55
A43: Technology / platform overhead (% of segment revenue) | B43: 0.05
A45: 6. ONE-TIME ONBOARDING FEE
A46: Onboarding / implementation fee, per new customer | B46: 35000
A47: Onboarding delivery margin | B47: 0.65
A49: 7. ENROLLMENT MATURITY RAMP — % of full target enrollment reached, by relationship year
A50: Relationship year | B50: % of target enrollment
A51: Year 1 (signing year) | B51: 0.2
A52: Year 2 | B52: 0.6
A53: Year 3+ | B53: 1
A55: New customers take time to build identification workflows, hire care teams, and ramp referral volume — modeled here as a 3-year maturity curve rather than an instant jump to full enrollment.
...

Sheet Segment Unit Economics
A1: SEGMENT UNIT ECONOMICS — per full-run-rate customer
A3: Blended lives per customer (from Assumptions) | B3: =Assumptions!B8 -> 41250
A5: Segment | B5: Enrolled members | C5: PMPM client fee | D5: Net CMS billing PMPM | E5: Total rev PMPM | F5: Delivery cost PMPM | G5: Tech overhead PMPM | H5: Total cost PMPM | I5: GP PMPM | J5: Margin
A6: Post-Acute Transitions | B6: =$B$3*Assumptions!B14 -> 330 | C6: =Assumptions!B23 -> 175 | D6: =Assumptions!B30 -> 80 | E6: =C6+D6 -> 255 | F6: =Assumptions!B39 -> 115 | G6: =E6*Assumptions!$B$43 -> 12.75 | H6: =F6+G6 -> 127.75 | I6: =E6-H6 -> 127.25 | J6: =I6/E6 -> 0.49901961
A7: Peri-Operative Optimization | B7: =$B$3*Assumptions!B15 -> 206.25 | C7: =Assumptions!B24 -> 195 | D7: =Assumptions!B31 -> 85 | E7: =C7+D7 -> 280 | F7: =Assumptions!B40 -> 130 | G7: =E7*Assumptions!$B$43 -> 14 | H7: =F7+G7 -> 144 | I7: =E7-H7 -> 136 | J7: =I7/E7 -> 0.48571429
A8: Complex Chronic CM | B8: =$B$3*Assumptions!B16 -> 1650 | C8: =Assumptions!B25 -> 85 | D8: =Assumptions!B32 -> 95 | E8: =C8+D8 -> 180 | F8: =Assumptions!B41 -> 55 | G8: =E8*Assumptions!$B$43 -> 9 | H8: =F8+G8 -> 64 | I8: =E8-H8 -> 116 | J8: =I8/E8 -> 0.64444444
A10: ANNUALIZED, PER FULL-RUN-RATE CUSTOMER
A11: Segment | B11: Annual revenue | C11: Annual cost | D11: Annual GP
A12: Post-Acute Transitions | B12: =B6*E6*12 -> 1009800 | C12: =B6*H6*12 -> 505890 | D12: =B12-C12 -> 503910
A13: Peri-Operative Optimization | B13: =B7*E7*12 -> 693000 | C13: =B7*H7*12 -> 356400 | D13: =B13-C13 -> 336600
A14: Complex Chronic CM | B14: =B8*E8*12 -> 3564000 | C14: =B8*H8*12 -> 1267200 | D14: =B14-C14 -> 2296800
A15: Blended total per customer | B15: =SUM(B12:B14) -> 5266800 | C15: =SUM(C12:C14) -> 2129490 | D15: =B15-C15 -> 3137310
A16: Blended margin | B16: =D15/B15 -> 0.59567669
A18: Full run-rate = a customer at 100% of target enrollment (relationship year 3+ per the maturity ramp on the Assumptions tab). The 3-Year Build tab applies the ramp curve and acquisition plan to phase customers in below full run-rate during their first two years.

Sheet 3-Year Build
A1: 3-YEAR BUILD
A3: COHORT MATRIX — revenue-equivalent customers by calendar year (ramp-adjusted, retention-adjusted)
A4: Cohort (signed in) | B4: New signed | C4: Year 1 | D4: Year 2 | E4: Year 3
A5: Cohort: Year 1 | B5: =Assumptions!B60 -> 2 | C5: =B5*Assumptions!B51 -> 0.4 | D5: =B5*Assumptions!$B$64*Assumptions!B52 -> 1.08 | E5: =B5*Assumptions!$B$64^2*Assumptions!B53 -> 1.62
A6: Cohort: Year 2 | B6: =Assumptions!B61 -> 6 | C6: =0 -> 0 | D6: =B6*Assumptions!B51 -> 1.2 | E6: =B6*Assumptions!$B$64*Assumptions!B52 -> 3.24
A7: Cohort: Year 3 | B7: =Assumptions!B62 -> 10 | C7: =0 -> 0 | D7: =0 -> 0 | E7: =B7*Assumptions!B51 -> 2
A8: Total revenue-equiv customers | C8: =SUM(C5:C7) -> 0.4 | D8: =SUM(D5:D7) -> 2.28 | E8: =SUM(E5:E7) -> 6.86
A10: CUMULATIVE CUSTOMERS & LIVES ON ROSTER (unweighted headcount, for context)
C11: Year 1 | D11: Year 2 | E11: Year 3
A12: Cumulative active customers | C12: =B5 -> 2 | D12: =B5*Assumptions!$B$64+B6 -> 7.8 | E12: =(B5*Assumptions!$B$64+B6)*Assumptions!$B$64+B7 -> 17.02
A13: Covered lives on roster | C13: =C12*Assumptions!B8 -> 82500 | D13: =D12*Assumptions!B8 -> 321750 | E13: =E12*Assumptions!B8 -> 702075
A15: REVENUE, COST & GROSS PROFIT
C16: Year 1 | D16: Year 2 | E16: Year 3
A17: Recurring revenue (PMPM + CMS billing) | C17: =C8*'Segment Unit Economics'!$B$15 -> 2106720 | D17: =D8*'Segment Unit Economics'!$B$15 -> 12008304 | E17: =E8*'Segment Unit Economics'!$B$15 -> 36130248
A18: Recurring cost | C18: =C8*'Segment Unit Economics'!$C$15 -> 851796 | D18: =D8*'Segment Unit Economics'!$C$15 -> 4855237.2 | E18: =E8*'Segment Unit Economics'!$C$15 -> 14608301
A19: Onboarding revenue (new signings) | C19: =B5*Assumptions!$B$46 -> 70000 | D19: =B6*Assumptions!$B$46 -> 210000 | E19: =B7*Assumptions!$B$46 -> 350000
A20: Onboarding cost | C20: =C19*(1-Assumptions!$B$47) -> 24500 | D20: =D19*(1-Assumptions!$B$47) -> 73500 | E20: =E19*(1-Assumptions!$B$47) -> 122500
A21: TOTAL REVENUE | C21: =C17+C19 -> 2176720 | D21: =D17+D19 -> 12218304 | E21: =E17+E19 -> 36480248
A22: TOTAL COST | C22: =C18+C20 -> 876296 | D22: =D18+D20 -> 4928737.2 | E22: =E18+E20 -> 14730801
A23: GROSS PROFIT | C23: =C21-C22 -> 1300424 | D23: =D21-D22 -> 7289566.8 | E23: =E21-E22 -> 21749447
A24: Gross margin | C24: =C23/C21 -> 0.59742365 | D24: =D23/D21 -> 0.59661036 | E24: =E23/E21 -> 0.59619788
A26: Revenue-equivalent customers phase in below full run-rate during their first two relationship years per the enrollment maturity ramp. A new cohort's onboarding fee is recognized in its signing year only.

Sheet Summary
A1: YIELD HEALTHCARE — PMPM LOB 3-YEAR SUMMARY
B3: Year 1 | C3: Year 2 | D3: Year 3
A4: Cumulative customers | B4: ='3-Year Build'!C12 -> 2 | C4: ='3-Year Build'!D12 -> 7.8 | D4: ='3-Year Build'!E12 -> 17.02
A6: Covered lives on roster | B6: ='3-Year Build'!C13 -> 82500 | C6: ='3-Year Build'!D13 -> 321750 | D6: ='3-Year Build'!E13 -> 702075
A8: Total revenue | B8: ='3-Year Build'!C21 -> 2176720 | C8: ='3-Year Build'!D21 -> 12218304 | D8: ='3-Year Build'!E21 -> 36480248
A10: Total cost | B10: ='3-Year Build'!C22 -> 876296 | C10: ='3-Year Build'!D22 -> 4928737.2 | D10: ='3-Year Build'!E22 -> 14730801
A12: Gross profit | B12: ='3-Year Build'!C23 -> 1300424 | C12: ='3-Year Build'!D23 -> 7289566.8 | D12: ='3-Year Build'!E23 -> 21749447
A14: Gross margin | B14: ='3-Year Build'!C24 -> 0.59742365 | C14: ='3-Year Build'!D24 -> 0.59661036 | D14: ='3-Year Build'!E24 -> 0.59619788
A17: All figures are illustrative planning estimates built from the Assumptions tab — refine enrollment rates, PMPM pricing, and delivery cost as real underwriting and staffing data become available.
