Workbook

Sheet Read Me
A2: YIELD HEALTH — TEAM EPISODE MANAGEMENT PRICING MODEL
B4: This workbook models three service tiers for Yield Health, a company managing hospitals through CMS's mandatory Transforming Episode Accountability Model (TEAM).
B6: Tabs:
B7: Assumptions — every input the model runs on (episode pricing, hospital sizing, tier pricing, staffing costs, CMS billing rates, customer acquisition plan). Blue text = editable input.
B8: Unit Economics — per-hospital revenue, cost, and margin for each tier at Small / Medium / Large hospital size, plus a size-blended figure.
B9: 3-Year Build — customer count ramp by tier and year, driving total revenue, cost, and gross profit.
B10: Summary — company-level rollup and a revenue-by-tier chart.
B12: How to use it: change any blue cell on the Assumptions tab and every other tab recalculates. All dollar figures are illustrative planning assumptions unless a source is cited in an adjacent note — this is a planning model, not a quote or a filed rate schedule.
B14: Sourced figures (verified July 2026): CMS TEAM final rule structure (188 CBSAs, ~741 mandated hospitals, 5 episode types, 3 participation tracks); 2026 Medicare Physician Fee Schedule national average rates for CPT 99495/99496 (Transitional Care Management), CPT 99490 (Chronic Care Management), and HCPCS G0023/G0024 (Principal Illness Navigation). Everything else — target prices, take rates, staffing ratios, customer ramp — is a labeled planning assumption for Yield Health to refine with real data.

Sheet Assumptions
A1: ASSUMPTIONS
A3: 1. EPISODE ECONOMICS (per TEAM episode)
A4: Episode Type | B4: Target Price ($) | C4: Volume Mix (%)
A5: Lower extremity joint replacement (LEJR) | B5: 21000 | C5: 0.55
A6: Surgical hip/femur fracture (SHFFT) | B6: 27000 | C6: 0.15
A7: Spinal fusion | B7: 34000 | C7: 0.1
A8: Coronary artery bypass graft (CABG) | B8: 42000 | C8: 0.1
A9: Major bowel procedure | B9: 24000 | C9: 0.1
A10: Blended weighted average target price / mix check | B10: =SUMPRODUCT(B5:B9,C5:C9) | C10: =SUM(C5:C9)
A11: Target prices are illustrative planning assumptions consistent with historical BPCI/CJR episode benchmarks and CMS's reported ~$18B / ~900K episodes (~$20K blended, all sites). Confirm against actual regional TEAM target prices once published for your markets.
A13: Standard-complexity share (LEJR + SHFFT + Major Bowel) | B13: =C5+C6+C9
A14: High-complexity share (Spinal Fusion + CABG) | B14: =C7+C8
A17: 2. HOSPITAL SIZE TIERS
A18: Size Tier | B18: Annual TEAM Episodes | C18: Share of 741 Hospitals
A19: Small | B19: 75 | C19: 0.4
A20: Medium | B20: 200 | C20: 0.4
A21: Large | B21: 450 | C21: 0.2
A22: Distribution check (should be 100%) | C22: =SUM(C19:C21)
A23: 741 hospitals mandated into TEAM across 188 CBSAs (CMS TEAM final rule). Size distribution and per-hospital episode volume are planning assumptions — replace with actual CMS-published hospital-level episode counts as they become available.
A25: 3. RECONCILIATION ASSUMPTIONS
A26: Share of episodes landing net-positive ("savers") with Yield Health | B26: 0.5
A27: Avg positive reconciliation captured per saver episode ($) | B27: 1800
A28: CMS's own data shows ~66% of hospitals are projected net payers absent intervention; this model assumes Yield Health's management shifts a managed hospital to roughly a 50/50 payer/saver split with a modest average per-episode gain among savers. Treat as a conservative planning input, not a guarantee.
A30: 4. TIER 1 — YIELD HEALTH ADVISORY (fixed-fee consulting)
B31: Small | C31: Medium | D31: Large
A32: Position Report (diagnostic only, one-time) | B32: 18000 | C32: 24000 | D32: 32000
A33: Full Advisory Engagement, incl. Position Report (one-time fee) | B33: 65000 | C33: 95000 | D33: 135000
A34: Delivery gross margin (advisory labor) | B34: 0.75
A35: Fixed-fee, project-based. No technology license, no ongoing staffing, no shared savings. 90-120 day engagement per the go-to-market deck (diagnose, prioritize, design governance/incentives).
A37: 5. TIER 2 — YIELD HEALTH PLATFORM (remote navigators + technology)
B38: Small | C38: Medium | D38: Large
A39: Onboarding / implementation fee (one-time) | B39: 20000 | C39: 32000 | D39: 48000
A40: Per-episode case management fee — standard complexity ($/episode) | B40: 950
A41: Per-episode case management fee — high complexity ($/episode) | B41: 1650
A42: Shared savings take rate — Standard option (upside only) | B42: 0.25
A43: Shared savings take rate — Aligned option (Yield Health shares downside) | B43: 0.38
A44: Downside share Yield Health absorbs under Aligned option | B44: 0.2
A45: Remote Navigator FTE — fully loaded cost/year ($) | B45: 95000
A46: Episodes managed per remote Navigator FTE | B46: 200
A47: Platform technology cost allocated per hospital/year ($) | B47: 15000
...

Sheet Unit Economics
A1: UNIT ECONOMICS — PER HOSPITAL, BY TIER AND SIZE
A3: HELPER CONSTANTS (derived from Assumptions)
A4: Blended per-episode fee, Tier 2 ($/episode) | B4: =Assumptions!$B$13*Assumptions!$B$40+Assumptions!$B$14*Assumptions!$B$41
A5: Shared savings revenue per episode, Tier 2 Standard ($) | B5: =Assumptions!$B$26*Assumptions!$B$27*Assumptions!$B$42
A6: Shared savings revenue per episode, Tier 2 Aligned ($) | B6: =Assumptions!$B$26*Assumptions!$B$27*Assumptions!$B$43
A7: CM billing revenue per episode, gross, Tier 3 ($) | B7: =Assumptions!$B$57*Assumptions!$B$58+Assumptions!$B$59*Assumptions!$B$60*Assumptions!$B$61
A8: CM billing revenue per episode, net to Yield Health, Tier 3 ($) | B8: =B7*Assumptions!$B$62
A9: Shared savings revenue per episode, Tier 3 ($) | B9: =Assumptions!$B$26*Assumptions!$B$27*Assumptions!$B$64
A12: TIER 1 — YIELD HEALTH ADVISORY
B13: Small | C13: Medium | D13: Large | E13: Blended
A14: Revenue (one-time engagement fee) | B14: =Assumptions!B33 | C14: =Assumptions!C33 | D14: =Assumptions!D33 | E14: =B14*Assumptions!$C$19+C14*Assumptions!$C$20+D14*Assumptions!$C$21
A15: Delivery cost | B15: =B14*(1-Assumptions!$B$34) | C15: =C14*(1-Assumptions!$B$34) | D15: =D14*(1-Assumptions!$B$34) | E15: =B15*Assumptions!$C$19+C15*Assumptions!$C$20+D15*Assumptions!$C$21
A16: Gross profit | B16: =B14-B15 | C16: =C14-C15 | D16: =D14-D15 | E16: =B16*Assumptions!$C$19+C16*Assumptions!$C$20+D16*Assumptions!$C$21
A17: Gross margin % | B17: =B16/B14 | C17: =C16/C14 | D17: =D16/D14 | E17: =B17*Assumptions!$C$19+C17*Assumptions!$C$20+D17*Assumptions!$C$21
A19: TIER 2 — YIELD HEALTH PLATFORM
B20: Small | C20: Medium | D20: Large | E20: Blended
A21: Annual episode volume | B21: =Assumptions!B19 | C21: =Assumptions!B20 | D21: =Assumptions!B21 | E21: =B21*Assumptions!$C$19+C21*Assumptions!$C$20+D21*Assumptions!$C$21
A22: Onboarding fee (one-time) | B22: =Assumptions!B39 | C22: =Assumptions!C39 | D22: =Assumptions!D39 | E22: =B22*Assumptions!$C$19+C22*Assumptions!$C$20+D22*Assumptions!$C$21
A23: Annual per-episode case management fee revenue | B23: =B21*$B$4 | C23: =C21*$B$4 | D23: =D21*$B$4 | E23: =B23*Assumptions!$C$19+C23*Assumptions!$C$20+D23*Assumptions!$C$21
A24: Annual shared savings revenue — Standard option | B24: =B21*$B$5 | C24: =C21*$B$5 | D24: =D21*$B$5 | E24: =B24*Assumptions!$C$19+C24*Assumptions!$C$20+D24*Assumptions!$C$21
A25: Annual shared savings revenue — Aligned option | B25: =B21*$B$6 | C25: =C21*$B$6 | D25: =D21*$B$6 | E25: =B25*Assumptions!$C$19+C25*Assumptions!$C$20+D25*Assumptions!$C$21
A26: Annual recurring revenue (Standard option) | B26: =B23+B24 | C26: =C23+C24 | D26: =D23+D24 | E26: =B26*Assumptions!$C$19+C26*Assumptions!$C$20+D26*Assumptions!$C$21
A27: Year-1 total revenue (incl. onboarding) | B27: =B22+B26 | C27: =C22+C26 | D27: =D22+D26 | E27: =B27*Assumptions!$C$19+C27*Assumptions!$C$20+D27*Assumptions!$C$21
A28: Remote Navigator FTEs required | B28: =B21/Assumptions!$B$46 | C28: =C21/Assumptions!$B$46 | D28: =D21/Assumptions!$B$46 | E28: =B28*Assumptions!$C$19+C28*Assumptions!$C$20+D28*Assumptions!$C$21
A29: Navigator staffing cost | B29: =B28*Assumptions!$B$45 | C29: =C28*Assumptions!$B$45 | D29: =D28*Assumptions!$B$45 | E29: =B29*Assumptions!$C$19+C29*Assumptions!$C$20+D29*Assumptions!$C$21
A30: Platform technology cost | B30: =Assumptions!$B$47 | C30: =Assumptions!$B$47 | D30: =Assumptions!$B$47 | E30: =B30*Assumptions!$C$19+C30*Assumptions!$C$20+D30*Assumptions!$C$21
A31: Onboarding delivery cost | B31: =B22*Assumptions!$B$48 | C31: =C22*Assumptions!$B$48 | D31: =D22*Assumptions!$B$48 | E31: =B31*Assumptions!$C$19+C31*Assumptions!$C$20+D31*Assumptions!$C$21
A32: Year-1 total cost | B32: =B29+B30+B31 | C32: =C29+C30+C31 | D32: =D29+D30+D31 | E32: =B32*Assumptions!$C$19+C32*Assumptions!$C$20+D32*Assumptions!$C$21
A33: Recurring annual cost (Year 2+) | B33: =B29+B30 | C33: =C29+C30 | D33: =D29+D30 | E33: =B33*Assumptions!$C$19+C33*Assumptions!$C$20+D33*Assumptions!$C$21
A34: Year-1 gross profit | B34: =B27-B32 | C34: =C27-C32 | D34: =D27-D32 | E34: =B34*Assumptions!$C$19+C34*Assumptions!$C$20+D34*Assumptions!$C$21
A35: Recurring gross profit (Year 2+) | B35: =B26-B33 | C35: =C26-C33 | D35: =D26-D33 | E35: =B35*Assumptions!$C$19+C35*Assumptions!$C$20+D35*Assumptions!$C$21
A36: Recurring gross margin % (Year 2+) | B36: =B35/B26 | C36: =C35/C26 | D36: =D35/D26 | E36: =B36*Assumptions!$C$19+C36*Assumptions!$C$20+D36*Assumptions!$C$21
A38: TIER 3 — YIELD HEALTH EMBEDDED
B39: Small | C39: Medium | D39: Large | E39: Blended
A40: Annual episode volume | B40: =Assumptions!B19 | C40: =Assumptions!B20 | D40: =Assumptions!B21 | E40: =B40*Assumptions!$C$19+C40*Assumptions!$C$20+D40*Assumptions!$C$21
A41: Setup / placement fee (one-time) | B41: =Assumptions!B53 | C41: =Assumptions!C53 | D41: =Assumptions!D53 | E41: =B41*Assumptions!$C$19+C41*Assumptions!$C$20+D41*Assumptions!$C$21
A42: Embedded FTEs required | B42: =B40/Assumptions!$B$56 | C42: =C40/Assumptions!$B$56 | D42: =D40/Assumptions!$B$56 | E42: =B42*Assumptions!$C$19+C42*Assumptions!$C$20+D42*Assumptions!$C$21
A43: Annual embedded-staff fee revenue (cost + management markup) | B43: =B42*Assumptions!$B$54*(1+Assumptions!$B$55) | C43: =C42*Assumptions!$B$54*(1+Assumptions!$B$55) | D43: =D42*Assumptions!$B$54*(1+Assumptions!$B$55) | E43: =B43*Assumptions!$C$19+C43*Assumptions!$C$20+D43*Assumptions!$C$21
A44: Annual CM billing revenue, net to Yield Health | B44: =B40*$B$8 | C44: =C40*$B$8 | D44: =D40*$B$8 | E44: =B44*Assumptions!$C$19+C44*Assumptions!$C$20+D44*Assumptions!$C$21
A45: Annual shared savings revenue | B45: =B40*$B$9 | C45: =C40*$B$9 | D45: =D40*$B$9 | E45: =B45*Assumptions!$C$19+C45*Assumptions!$C$20+D45*Assumptions!$C$21
...

Sheet 3-Year Build
A1: 3-YEAR REVENUE BUILD
A2: Uses the size-blended unit economics from the 'Unit Economics' tab and the customer acquisition plan from 'Assumptions' §7. Every cell below is a formula -- change the acquisition plan or any pricing assumption and this rebuilds automatically.
B4: Year 1 | C4: Year 2 | D4: Year 3
A5: NEW CUSTOMERS SIGNED
A6: New Advisory engagements | B6: =Assumptions!B69 | C6: =Assumptions!C69 | D6: =Assumptions!D69
A7: New Platform customers | B7: =Assumptions!B70 | C7: =Assumptions!C70 | D7: =Assumptions!D70
A8: New Embedded customers | B8: =Assumptions!B71 | C8: =Assumptions!C71 | D8: =Assumptions!D71
A10: CUMULATIVE ACTIVE CUSTOMERS (recurring tiers, after retention)
A11: Cumulative active — Platform | B11: =B7 | C11: =B11*Assumptions!$B$72+C7 | D11: =C11*Assumptions!$B$72+D7
A12: Cumulative active — Embedded | B12: =B8 | C12: =B12*Assumptions!$B$73+C8 | D12: =C12*Assumptions!$B$73+D8
A14: HEADCOUNT REQUIRED (planning reference)
A15: Remote Navigator FTEs (Platform) | B15: =B11*'Unit Economics'!$E$28 | C15: =C11*'Unit Economics'!$E$28 | D15: =D11*'Unit Economics'!$E$28
A16: Embedded RN Care Manager FTEs (Embedded) | B16: =B12*'Unit Economics'!$E$42 | C16: =C12*'Unit Economics'!$E$42 | D16: =D12*'Unit Economics'!$E$42
A18: REVENUE
A19: Advisory revenue | B19: =B6*'Unit Economics'!$E$14 | C19: =C6*'Unit Economics'!$E$14 | D19: =D6*'Unit Economics'!$E$14
A20: Platform revenue (new-customer Year-1 + retained recurring) | B20: =B7*'Unit Economics'!$E$27+(B11-B7)*'Unit Economics'!$E$26 | C20: =C7*'Unit Economics'!$E$27+(C11-C7)*'Unit Economics'!$E$26 | D20: =D7*'Unit Economics'!$E$27+(D11-D7)*'Unit Economics'!$E$26
A21: Embedded revenue (new-customer Year-1 + retained recurring) | B21: =B8*'Unit Economics'!$E$47+(B12-B8)*'Unit Economics'!$E$46 | C21: =C8*'Unit Economics'!$E$47+(C12-C8)*'Unit Economics'!$E$46 | D21: =D8*'Unit Economics'!$E$47+(D12-D8)*'Unit Economics'!$E$46
A22: TOTAL REVENUE | B22: =SUM(B19:B21) | C22: =SUM(C19:C21) | D22: =SUM(D19:D21)
A24: COST
A25: Advisory cost | B25: =B6*'Unit Economics'!$E$15 | C25: =C6*'Unit Economics'!$E$15 | D25: =D6*'Unit Economics'!$E$15
A26: Platform cost (new-customer Year-1 + retained recurring) | B26: =B7*'Unit Economics'!$E$32+(B11-B7)*'Unit Economics'!$E$33 | C26: =C7*'Unit Economics'!$E$32+(C11-C7)*'Unit Economics'!$E$33 | D26: =D7*'Unit Economics'!$E$32+(D11-D7)*'Unit Economics'!$E$33
A27: Embedded cost (new-customer Year-1 + retained recurring) | B27: =B8*'Unit Economics'!$E$51+(B12-B8)*'Unit Economics'!$E$52 | C27: =C8*'Unit Economics'!$E$51+(C12-C8)*'Unit Economics'!$E$52 | D27: =D8*'Unit Economics'!$E$51+(D12-D8)*'Unit Economics'!$E$52
A28: TOTAL COST | B28: =SUM(B25:B27) | C28: =SUM(C25:C27) | D28: =SUM(D25:D27)
A30: PROFITABILITY
A31: Gross profit | B31: =B22-B28 | C31: =C22-C28 | D31: =D22-D28
A32: Gross margin % | B32: =B31/B22 | C32: =C31/C22 | D32: =D31/D22

Sheet Summary
A1: YIELD HEALTH — 3-YEAR SUMMARY
A3: REVENUE BY TIER ($)
B4: Year 1 | C4: Year 2 | D4: Year 3
A5: Advisory | B5: ='3-Year Build'!B19 | C5: ='3-Year Build'!C19 | D5: ='3-Year Build'!D19
A6: Platform | B6: ='3-Year Build'!B20 | C6: ='3-Year Build'!C20 | D6: ='3-Year Build'!D20
A7: Embedded | B7: ='3-Year Build'!B21 | C7: ='3-Year Build'!C21 | D7: ='3-Year Build'!D21
A8: Total Revenue | B8: ='3-Year Build'!B22 | C8: ='3-Year Build'!C22 | D8: ='3-Year Build'!D22
A10: Total Gross Profit | B10: ='3-Year Build'!B31 | C10: ='3-Year Build'!C31 | D10: ='3-Year Build'!D31
A11: Gross Margin % | B11: ='3-Year Build'!B32 | C11: ='3-Year Build'!C32 | D11: ='3-Year Build'!D32
A13: Active customer relationships (year-end)
A14: Advisory engagements (that year) | B14: ='3-Year Build'!B6 | C14: ='3-Year Build'!C6 | D14: ='3-Year Build'!D6
A15: Platform (cumulative active) | B15: ='3-Year Build'!B11 | C15: ='3-Year Build'!C11 | D15: ='3-Year Build'!D11
A16: Embedded (cumulative active) | B16: ='3-Year Build'!B12 | C16: ='3-Year Build'!C12 | D16: ='3-Year Build'!D12
A18: All figures are illustrative planning assumptions built up from the Assumptions and Unit Economics tabs. Refine episode pricing, take rates, and the acquisition ramp as real contract data comes in.
